Traceback (most recent call last):
  File "/home/codespace/.local/lib/python3.12/site-packages/jupyter_core/utils/__init__.py", line 154, in wrapped
    asyncio.get_running_loop()
RuntimeError: no running event loop

During handling of the above exception, another exception occurred:

Traceback (most recent call last):
  File "/usr/local/python/3.12.1/lib/python3.12/site-packages/jupyter_cache/executors/utils.py", line 58, in single_nb_execution
    executenb(
  File "/home/codespace/.local/lib/python3.12/site-packages/nbclient/client.py", line 1319, in execute
    return NotebookClient(nb=nb, resources=resources, km=km, **kwargs).execute()
           ^^^^^^^^^^^^^^^^^^^^^^^^^^^^^^^^^^^^^^^^^^^^^^^^^^^^^^^^^^^^^^^^^^^^^
  File "/home/codespace/.local/lib/python3.12/site-packages/jupyter_core/utils/__init__.py", line 158, in wrapped
    return loop.run_until_complete(inner)
           ^^^^^^^^^^^^^^^^^^^^^^^^^^^^^^
  File "/usr/local/python/3.12.1/lib/python3.12/asyncio/base_events.py", line 684, in run_until_complete
    return future.result()
           ^^^^^^^^^^^^^^^
  File "/home/codespace/.local/lib/python3.12/site-packages/nbclient/client.py", line 709, in async_execute
    await self.async_execute_cell(
  File "/home/codespace/.local/lib/python3.12/site-packages/nbclient/client.py", line 1062, in async_execute_cell
    await self._check_raise_for_error(cell, cell_index, exec_reply)
  File "/home/codespace/.local/lib/python3.12/site-packages/nbclient/client.py", line 918, in _check_raise_for_error
    raise CellExecutionError.from_cell_and_msg(cell, exec_reply_content)
nbclient.exceptions.CellExecutionError: An error occurred while executing the following cell:
------------------
import openeo
import os
import xarray as xr
import pandas as pd
connection = openeo.connect("openeo.dataspace.copernicus.eu").authenticate_oidc()

coordinates = [
    [113.68677516434411, -8.165890715645048],
    [113.68767635393294, -8.178366137853942],
    [113.7212614574645, -8.178954488616213],
    [113.72266252355564, -8.167199225119404],
    [113.68677516434411, -8.165890715645048]
]

# 3️⃣ Hitung bounding box otomatis dari koordinat
lons = [coord[0] for coord in coordinates]
lats = [coord[1] for coord in coordinates]

bbox = {
    "west": min(lons),
    "south": min(lats),
    "east": max(lons),
    "north": max(lats)
}

# 4️⃣ Tampilkan area yang tercakup
print("🗺️ Area coverage (Jember AOI):")
print(f"Longitude: {bbox['west']}°E to {bbox['east']}°E")
print(f"Latitude:  {bbox['south']}°S to {bbox['north']}°S")

# 5️⃣ Buat AOI GeoJSON sederhana untuk dipakai di OpenEO
aoi = {
    "type": "Polygon",
    "coordinates": [coordinates]
}

print("\n✅ AOI untuk Jember sudah siap digunakan.")

------------------


[31m---------------------------------------------------------------------------[39m
[31mModuleNotFoundError[39m                       Traceback (most recent call last)
[36mCell[39m[36m [39m[32mIn[1][39m[32m, line 1[39m
[32m----> [39m[32m1[39m [38;5;28;01mimport[39;00m[38;5;250m [39m[34;01mopeneo[39;00m
[32m      2[39m [38;5;28;01mimport[39;00m[38;5;250m [39m[34;01mos[39;00m
[32m      3[39m [38;5;28;01mimport[39;00m[38;5;250m [39m[34;01mxarray[39;00m[38;5;250m [39m[38;5;28;01mas[39;00m[38;5;250m [39m[34;01mxr[39;00m

[31mModuleNotFoundError[39m: No module named 'openeo'

